<robot name="parallel_link_gripper" xmlns:xacro="http://www.ros.org/wiki/xacro">
  <xacro:macro name="mk_parallel_gripper" params="ns">
    <link name="${ns}/base_link" />
    <joint name="${ns}/base_link_to_base" type="fixed">
      <parent link="${ns}/base_link" />
      <child link="${ns}/body" />
      <origin rpy="0 0 0" xyz="0 0 0" />
    </joint>
    <link name="${ns}/body">
      <visual>
        <origin xyz="0.002 0 -0.017" rpy="0 0 0" />
        <geometry>
          <mesh filename="package://gripper_description/mesh/gripper_mount__list_gggmxkb4ygsnke_default.stl" />
        </geometry>
        <material name="gripper_mount__list_gggmxkb4ygsnke_default_material">
          <color rgba="0.231373 0.380392 0.705882 1.0" />
        </material>
      </visual>
      <collision>
        <origin xyz="0.0205 0 0" rpy="0 0 0" />
        <geometry>
          <box size="0.041 0.066 0.04" />
        </geometry>
      </collision>
      <collision>
        <origin xyz="0.045 0 0" rpy="0 0 0" />
        <geometry>
          <box size="0.008 0.048 0.04" />
        </geometry>
      </collision>
      <visual>
        <origin xyz="0.002 0 -0.017" rpy="0 0 0" />
        <geometry>
          <mesh filename="package://gripper_description/mesh/gripper_x430_shell_rhs__list_gggmxkb4ygsnke_default.stl" />
        </geometry>
        <material name="gripper_x430_shell_rhs__list_gggmxkb4ygsnke_default_material">
          <color rgba="0.4 0.4 0.4 1.0" />
        </material>
      </visual>
      <visual>
        <origin xyz="0.002 0 -0.017" rpy="0 0 0" />
        <geometry>
          <mesh filename="package://gripper_description/mesh/gripper_bracket_rhs__list_gggmxkb4ygsnke_default.stl" />
        </geometry>
        <material name="gripper_bracket_rhs__list_gggmxkb4ygsnke_default_material">
          <color rgba="0.917647 0.917647 0.917647 1.0" />
        </material>
      </visual>
      <collision>
        <origin xyz="0.0215 -0.034 0" rpy="0 0 0" />
        <geometry>
          <box size="0.03 0.003 0.02" />
        </geometry>
      </collision>
      <collision>
        <origin xyz="0.0173 -0.04 0" rpy="0 0 0" />
        <geometry>
          <cylinder length="0.02" radius="0.005" />
        </geometry>
      </collision>
      <visual>
        <origin xyz="0.03725 0.015 0.019" rpy="0 0 -1.5708" />
        <geometry>
          <mesh filename="package://gripper_description/mesh/dynamixel_casing__list_ndk53xfpevccij_default.stl" />
        </geometry>
        <material name="dynamixel_casing__list_ndk53xfpevccij_default_material">
          <color rgba="0.615686 0.811765 0.929412 1.0" />
        </material>
      </visual>
      <visual>
        <origin xyz="0.002 0.0615 -0.017" rpy="0 0 0" />
        <geometry>
          <mesh filename="package://gripper_description/mesh/gripper_bracket_pad__list_gggmxkb4ygsnke_default.stl" />
        </geometry>
        <material name="gripper_bracket_pad__list_gggmxkb4ygsnke_default_material">
          <color rgba="0.768627 0.886275 0.952941 1.0" />
        </material>
      </visual>
      <collision>
        <origin xyz="0.0215 0.0307 0" rpy="0 0 0" />
        <geometry>
          <box size="0.03 0.003 0.02" />
        </geometry>
      </collision>
      <visual>
        <origin xyz="0.002 0 0.017" rpy="-3.14159 0 0" />
        <geometry>
          <mesh filename="package://gripper_description/mesh/gripper_bracket_rhs__list_gggmxkb4ygsnke_default.stl" />
        </geometry>
        <material name="gripper_bracket_rhs__list_gggmxkb4ygsnke_default_material">
          <color rgba="0.917647 0.917647 0.917647 1.0" />
        </material>
      </visual>
      <collision>
        <origin xyz="0.0215 0.034 0" rpy="-3.14159 0 0" />
        <geometry>
          <box size="0.03 0.003 0.02" />
        </geometry>
      </collision>
      <collision>
        <origin xyz="0.0173 0.04 0" rpy="-3.14159 0 0" />
        <geometry>
          <cylinder length="0.02" radius="0.005" />
        </geometry>
      </collision>
      <inertial>
        <origin xyz="0.0224723 0.00874655 0.000222665" rpy="0 0 0" />
        <mass value="0.157422" />
        <inertia ixx="6.18655e-05" ixy="-4.90692e-06" ixz="1.13998e-08" iyy="5.05121e-05" iyz="-2.19198e-07" izz="7.60343e-05" />
      </inertial>
    </link>
    <link name="${ns}/lhs_inner_beam">
      <visual>
        <origin xyz="0 0.015 -0.017" rpy="0 0 3.14159" />
        <geometry>
          <mesh filename="package://gripper_description/mesh/rod_inner_lhs_top.stl" />
        </geometry>
        <material name="rod_inner_lhs_top_material">
          <color rgba="0.231373 0.380392 0.705882 1.0" />
        </material>
      </visual>
      <collision>
        <origin xyz="0 0 0.0045" rpy="0 0 3.14159" />
        <geometry>
          <cylinder length="0.005" radius="0.013" />
        </geometry>
      </collision>
      <collision>
        <origin xyz="0 -0.0195 0.0045" rpy="0 0 3.14159" />
        <geometry>
          <box size="0.01 0.039 0.005" />
        </geometry>
      </collision>
      <visual>
        <origin xyz="0 0.015 -0.024" rpy="0 0 0" />
        <geometry>
          <mesh filename="package://gripper_description/mesh/rod_inner_bottom.stl" />
        </geometry>
        <material name="rod_inner_bottom_material">
          <color rgba="0.972549 0.529412 0.00392157 1.0" />
        </material>
      </visual>
      <collision>
        <origin xyz="0 -0.02 -0.039" rpy="0 0 0" />
        <geometry>
          <box size="0.012 0.036 0.005" />
        </geometry>
      </collision>
      <collision>
        <origin xyz="0 0 -0.039" rpy="0 0 0" />
        <geometry>
          <cylinder length="0.005" radius="0.011" />
        </geometry>
      </collision>
      <visual>
        <origin xyz="0 0 0.002" rpy="0 0 0" />
        <geometry>
          <mesh filename="package://gripper_description/mesh/dynamixel_horn__list_ndk53xfpevccij_default.stl" />
        </geometry>
        <material name="dynamixel_horn__list_ndk53xfpevccij_default_material">
          <color rgba="0.231373 0.380392 0.705882 1.0" />
        </material>
      </visual>
      <inertial>
        <origin xyz="-0.000694637 -0.00752629 -0.013178" rpy="0 0 0" />
        <mass value="0.00897747" />
        <inertia ixx="5.34685e-06" ixy="4.25659e-08" ixz="1.10241e-07" iyy="4.1093e-06" iyz="-5.49535e-07" izz="1.77758e-06" />
      </inertial>
    </link>
    <link name="${ns}/lhs_claw">
      <visual>
        <origin xyz="0 -0.006 0" rpy="0 0 0" />
        <geometry>
          <mesh filename="package://gripper_description/mesh/jaw_plate.stl" />
        </geometry>
        <material name="jaw_plate_material">
          <color rgba="0.980392 0.796078 0.262745 1.0" />
        </material>
      </visual>
      <collision>
        <origin xyz="0 -0.006 0" rpy="0 0 0" />
        <geometry>
          <mesh filename="package://gripper_description/mesh/jaw_plate.stl" />
        </geometry>
        <material name="jaw_plate_material">
          <color rgba="0.980392 0.796078 0.262745 1.0" />
        </material>
      </collision>
      <inertial>
        <origin xyz="0.00954335 0.0109092 -3.55182e-09" rpy="0 0 0" />
        <mass value="0.0706194" />
        <inertia ixx="1.06828e-05" ixy="6.2682e-06" ixz="0" iyy="3.9212e-05" iyz="1.29448e-11" izz="3.75191e-05" />
      </inertial>
    </link>
    <joint name="${ns}/lhs_j3" type="continuous">
      <origin xyz="0 -0.035 -0.017" rpy="0 0 3.14159" />
      <parent link="${ns}/lhs_inner_beam" />
      <child link="${ns}/lhs_claw" />
      <axis xyz="0 0 1" />
      <limit effort="1" velocity="20" />
      <joint_properties friction="0.0" />
      <mimic joint="${ns}/lhs_j1" multiplier="-1" offset="0" />
    </joint>
    <joint name="${ns}/lhs_j1" type="revolute">
      <origin xyz="0.03725 0.015 0.017" rpy="0 0 -3.14159" />
      <parent link="${ns}/base_link" />
      <child link="${ns}/lhs_inner_beam" />
      <axis xyz="0 0 1" />
      <limit effort="1" velocity="20" lower="-1.5708" upper="0.15708" />
      <joint_properties friction="0.0" />
    </joint>
    <link name="${ns}/lhs_outer_beam">
      <visual>
        <origin xyz="0.02 0.025 0.0025" rpy="-3.14159 0 0" />
        <geometry>
          <mesh filename="package://gripper_description/mesh/rod_outer.stl" />
        </geometry>
        <material name="rod_outer_material">
          <color rgba="0.498039 0.498039 0.498039 1.0" />
        </material>
      </visual>
      <collision>
        <origin xyz="0 -0.0175 0" rpy="-3.14159 0 0" />
        <geometry>
          <box size="0.01 0.043 0.005" />
        </geometry>
      </collision>
      <inertial>
        <origin xyz="0 -0.0175 0" rpy="0 0 0" />
        <mass value="0.00168556" />
        <inertia ixx="2.35764e-07" ixy="0" ixz="0" iyy="1.24039e-08" iyz="0" izz="2.41145e-07" />
      </inertial>
    </link>
    <joint name="${ns}/lhs_j2" type="continuous">
      <origin xyz="0.01725 0.04 0" rpy="-3.14159 0 0" />
      <parent link="${ns}/base_link" />
      <child link="${ns}/lhs_outer_beam" />
      <axis xyz="0 0 1" />
      <limit effort="1" velocity="20" />
      <joint_properties friction="0.0" />
      <mimic joint="${ns}/lhs_j1" multiplier="-1" offset="0" />
    </joint>
    <link name="${ns}/rhs_inner_beam">
      <visual>
        <origin xyz="-0.015 0 0" rpy="0 0 1.5708" />
        <geometry>
          <mesh filename="package://gripper_description/mesh/rod_inner_rhs_top.stl" />
        </geometry>
        <material name="rod_inner_rhs_top_material">
          <color rgba="0.768627 0.886275 0.952941 1.0" />
        </material>
      </visual>
      <collision>
        <origin xyz="0 0 0.0215" rpy="0 0 1.5708" />
        <geometry>
          <cylinder length="0.005" radius="0.013" />
        </geometry>
      </collision>
      <collision>
        <origin xyz="0.0195 0 0.0215" rpy="0 0 1.5708" />
        <geometry>
          <box size="0.01 0.039 0.005" />
        </geometry>
      </collision>
      <visual>
        <origin xyz="-0.015 0 -0.007" rpy="0 0 1.5708" />
        <geometry>
          <mesh filename="package://gripper_description/mesh/rod_inner_bottom.stl" />
        </geometry>
        <material name="rod_inner_bottom_material">
          <color rgba="0.972549 0.529412 0.00392157 1.0" />
        </material>
      </visual>
      <collision>
        <origin xyz="0.02 0 -0.022" rpy="0 0 1.5708" />
        <geometry>
          <box size="0.012 0.036 0.005" />
        </geometry>
      </collision>
      <collision>
        <origin xyz="0 0 -0.022" rpy="0 0 1.5708" />
        <geometry>
          <cylinder length="0.005" radius="0.011" />
        </geometry>
      </collision>
      <inertial>
        <origin xyz="0.00901442 0.000756382 0.000852503" rpy="0 0 0" />
        <mass value="0.00744734" />
        <inertia ixx="3.68765e-06" ixy="4.3779e-08" ixz="3.57846e-07" iyy="4.8283e-06" iyz="-1.16308e-07" izz="1.61067e-06" />
      </inertial>
    </link>
    <link name="${ns}/rhs_claw">
      <visual>
        <origin xyz="0 -0.006 0" rpy="0 0 0" />
        <geometry>
          <mesh filename="package://gripper_description/mesh/jaw_plate.stl" />
        </geometry>
        <material name="jaw_plate_material">
          <color rgba="0.980392 0.796078 0.262745 1.0" />
        </material>
      </visual>
      <collision>
        <origin xyz="0 -0.006 0" rpy="0 0 0" />
        <geometry>
          <mesh filename="package://gripper_description/mesh/jaw_plate.stl" />
        </geometry>
        <material name="jaw_plate_material">
          <color rgba="0.980392 0.796078 0.262745 1.0" />
        </material>
      </collision>
      <inertial>
        <origin xyz="0.00954335 0.0109092 -3.55182e-09" rpy="0 0 0" />
        <mass value="0.0706194" />
        <inertia ixx="1.06828e-05" ixy="6.2682e-06" ixz="0" iyy="3.9212e-05" iyz="1.29448e-11" izz="3.75191e-05" />
      </inertial>
    </link>
    <joint name="${ns}/rhs_j3" type="continuous">
      <origin xyz="0.035 0 0" rpy="-3.14159 0 1.5708" />
      <parent link="${ns}/rhs_inner_beam" />
      <child link="${ns}/rhs_claw" />
      <axis xyz="0 0 1" />
      <limit effort="1" velocity="20" />
      <joint_properties friction="0.0" />
      <mimic joint="${ns}/lhs_j1" multiplier="-1" offset="0" />
    </joint>
    <joint name="${ns}/rhs_j1" type="continuous">
      <origin xyz="0.03725 -0.015 0" rpy="0 0 -1.5708" />
      <parent link="${ns}/base_link" />
      <child link="${ns}/rhs_inner_beam" />
      <axis xyz="0 0 1" />
      <limit effort="1" velocity="20" lower="-0.174533" upper="1.5708" />
      <joint_properties friction="0.0" />
      <mimic joint="${ns}/lhs_j1" multiplier="-1" offset="0" />
    </joint>
    <link name="${ns}/rhs_outer_beam">
      <visual>
        <origin xyz="0.02 0.06 0.0025" rpy="3.14159 0 0" />
        <geometry>
          <mesh filename="package://gripper_description/mesh/rod_outer.stl" />
        </geometry>
        <material name="rod_outer_material">
          <color rgba="0.498039 0.498039 0.498039 1.0" />
        </material>
      </visual>
      <collision>
        <origin xyz="0 0.0175 0" rpy="3.14159 0 0" />
        <geometry>
          <box size="0.01 0.043 0.005" />
        </geometry>
      </collision>
      <inertial>
        <origin xyz="0 0.0175 0" rpy="0 0 0" />
        <mass value="0.00168556" />
        <inertia ixx="2.35764e-07" ixy="0" ixz="0" iyy="1.24039e-08" iyz="0" izz="2.41145e-07" />
      </inertial>
    </link>
    <joint name="${ns}/rhs_j2" type="continuous">
      <origin xyz="0.01725 -0.04 0" rpy="-3.14159 0 0" />
      <parent link="${ns}/base_link" />
      <child link="${ns}/rhs_outer_beam" />
      <axis xyz="0 0 1" />
      <limit effort="1" velocity="20" />
      <joint_properties friction="0.0" />
      <mimic joint="${ns}/lhs_j1" multiplier="1" offset="0" />
    </joint>
    <joint name="${ns}/Base2TCP" type="fixed">
      <origin xyz="0.098 0 0" rpy="0 0 0" />
      <parent link="${ns}/base_link" />
      <child link="${ns}/TCP" />
    </joint>
    <link name="${ns}/TCP" />
    <transmission name="${ns}/lhs_j1_transmission">
      <type>transmission_interface/SimpleTransmission</type>
      <joint name="${ns}/lhs_j1">
        <hardwareInterface>hardware_interface/PositionJointInterface</hardwareInterface>
      </joint>
      <actuator name="${ns}/lhs_j1_actuator">
        <mechanicalReduction>1</mechanicalReduction>
      </actuator>
    </transmission>
  </xacro:macro>
</robot>