<robot name="parallel_link_gripper">
  <link name="base_link" />
  <joint name="base_link_to_base" type="fixed">
    <parent link="base_link" />
    <child link="body" />
    <origin rpy="0.0 0 0" xyz="0 0 0" />
  </joint>
  <link name="body">
    <visual>
      <origin xyz="0.002 2.84109e-20 -0.017" rpy="-9.02876e-31 -0 -6.57608e-32" />
      <geometry>
        <mesh filename="package://gripper_description/mesh/gripper_mount__list_gggmxkb4ygsnke_default.stl" />
      </geometry>
      <material name="gripper_mount__list_gggmxkb4ygsnke_default_material">
        <color rgba="0.231373 0.380392 0.705882 1.0" />
      </material>
    </visual>
    <collision>
      <origin xyz="0.002 2.84109e-20 -0.017" rpy="-9.02876e-31 -0 -6.57608e-32" />
      <geometry>
        <mesh filename="package://gripper_description/mesh/gripper_mount__list_gggmxkb4ygsnke_default.stl" />
      </geometry>
      <material name="gripper_mount__list_gggmxkb4ygsnke_default_material">
        <color rgba="0.231373 0.380392 0.705882 1.0" />
      </material>
    </collision>
    <visual>
      <origin xyz="0.002 1.04368e-17 -0.017" rpy="2.28667e-16 3.14417e-16 -1.65045e-30" />
      <geometry>
        <mesh filename="package://gripper_description/mesh/gripper_x430_shell_rhs__list_gggmxkb4ygsnke_default.stl" />
      </geometry>
      <material name="gripper_x430_shell_rhs__list_gggmxkb4ygsnke_default_material">
        <color rgba="0.4 0.4 0.4 1.0" />
      </material>
    </visual>
    <collision>
      <origin xyz="0.002 1.04368e-17 -0.017" rpy="2.28667e-16 3.14417e-16 -1.65045e-30" />
      <geometry>
        <mesh filename="package://gripper_description/mesh/gripper_x430_shell_rhs__list_gggmxkb4ygsnke_default.stl" />
      </geometry>
      <material name="gripper_x430_shell_rhs__list_gggmxkb4ygsnke_default_material">
        <color rgba="0.4 0.4 0.4 1.0" />
      </material>
    </collision>
    <visual>
      <origin xyz="0.002 1.73756e-17 -0.017" rpy="2.28667e-16 3.14417e-16 -1.65045e-30" />
      <geometry>
        <mesh filename="package://gripper_description/mesh/gripper_bracket_rhs__list_gggmxkb4ygsnke_default.stl" />
      </geometry>
      <material name="gripper_bracket_rhs__list_gggmxkb4ygsnke_default_material">
        <color rgba="0.917647 0.917647 0.917647 1.0" />
      </material>
    </visual>
    <collision>
      <origin xyz="0.002 1.73756e-17 -0.017" rpy="2.28667e-16 3.14417e-16 -1.65045e-30" />
      <geometry>
        <mesh filename="package://gripper_description/mesh/gripper_bracket_rhs__list_gggmxkb4ygsnke_default.stl" />
      </geometry>
      <material name="gripper_bracket_rhs__list_gggmxkb4ygsnke_default_material">
        <color rgba="0.917647 0.917647 0.917647 1.0" />
      </material>
    </collision>
    <visual>
      <origin xyz="0.03725 0.015 0.019" rpy="-4.91725e-16 1.9792e-14 -1.5708" />
      <geometry>
        <mesh filename="package://gripper_description/mesh/dynamixel_casing__list_ndk53xfpevccij_default.stl" />
      </geometry>
      <material name="dynamixel_casing__list_ndk53xfpevccij_default_material">
        <color rgba="0.615686 0.811765 0.929412 1.0" />
      </material>
    </visual>
    <collision>
      <origin xyz="0.03725 0.015 0.019" rpy="-4.91725e-16 1.9792e-14 -1.5708" />
      <geometry>
        <mesh filename="package://gripper_description/mesh/dynamixel_casing__list_ndk53xfpevccij_default.stl" />
      </geometry>
      <material name="dynamixel_casing__list_ndk53xfpevccij_default_material">
        <color rgba="0.615686 0.811765 0.929412 1.0" />
      </material>
    </collision>
    <visual>
      <origin xyz="0.002 0.0615 -0.017" rpy="2.28667e-16 3.71583e-16 7.45931e-17" />
      <geometry>
        <mesh filename="package://gripper_description/mesh/gripper_bracket_pad__list_gggmxkb4ygsnke_default.stl" />
      </geometry>
      <material name="gripper_bracket_pad__list_gggmxkb4ygsnke_default_material">
        <color rgba="0.768627 0.886275 0.952941 1.0" />
      </material>
    </visual>
    <collision>
      <origin xyz="0.002 0.0615 -0.017" rpy="2.28667e-16 3.71583e-16 7.45931e-17" />
      <geometry>
        <mesh filename="package://gripper_description/mesh/gripper_bracket_pad__list_gggmxkb4ygsnke_default.stl" />
      </geometry>
      <material name="gripper_bracket_pad__list_gggmxkb4ygsnke_default_material">
        <color rgba="0.768627 0.886275 0.952941 1.0" />
      </material>
    </collision>
    <visual>
      <origin xyz="0.002 -1.8235e-17 0.017" rpy="-3.14159 3.14417e-16 5.37331e-16" />
      <geometry>
        <mesh filename="package://gripper_description/mesh/gripper_bracket_rhs__list_gggmxkb4ygsnke_default.stl" />
      </geometry>
      <material name="gripper_bracket_rhs__list_gggmxkb4ygsnke_default_material">
        <color rgba="0.917647 0.917647 0.917647 1.0" />
      </material>
    </visual>
    <collision>
      <origin xyz="0.002 -1.8235e-17 0.017" rpy="-3.14159 3.14417e-16 5.37331e-16" />
      <geometry>
        <mesh filename="package://gripper_description/mesh/gripper_bracket_rhs__list_gggmxkb4ygsnke_default.stl" />
      </geometry>
      <material name="gripper_bracket_rhs__list_gggmxkb4ygsnke_default_material">
        <color rgba="0.917647 0.917647 0.917647 1.0" />
      </material>
    </collision>
    <inertial>
      <origin xyz="0.0224723 0.00874655 0.000222665" rpy="0 0 0" />
      <mass value="0.157422" />
      <inertia ixx="6.18655e-05" ixy="-4.90692e-06" ixz="1.13998e-08" iyy="5.05121e-05" iyz="-2.19198e-07" izz="7.60343e-05" />
    </inertial>
  </link>
  <link name="rod_inner_lhs">
    <visual>
      <origin xyz="6.93889e-18 0.015 -0.017" rpy="1.32156e-16 -3.87474e-17 3.14159" />
      <geometry>
        <mesh filename="package://gripper_description/mesh/rod_inner_lhs_top.stl" />
      </geometry>
      <material name="rod_inner_lhs_top_material">
        <color rgba="0.231373 0.380392 0.705882 1.0" />
      </material>
    </visual>
    <collision>
      <origin xyz="6.93889e-18 0.015 -0.017" rpy="1.32156e-16 -3.87474e-17 3.14159" />
      <geometry>
        <mesh filename="package://gripper_description/mesh/rod_inner_lhs_top.stl" />
      </geometry>
      <material name="rod_inner_lhs_top_material">
        <color rgba="0.231373 0.380392 0.705882 1.0" />
      </material>
    </collision>
    <visual>
      <origin xyz="1.38778e-17 0.015 -0.024" rpy="-1.46561e-16 3.87474e-17 -3.60822e-16" />
      <geometry>
        <mesh filename="package://gripper_description/mesh/rod_inner_bottom.stl" />
      </geometry>
      <material name="rod_inner_bottom_material">
        <color rgba="0.972549 0.529412 0.00392157 1.0" />
      </material>
    </visual>
    <collision>
      <origin xyz="1.38778e-17 0.015 -0.024" rpy="-1.46561e-16 3.87474e-17 -3.60822e-16" />
      <geometry>
        <mesh filename="package://gripper_description/mesh/rod_inner_bottom.stl" />
      </geometry>
      <material name="rod_inner_bottom_material">
        <color rgba="0.972549 0.529412 0.00392157 1.0" />
      </material>
    </collision>
    <visual>
      <origin xyz="0 0 0.002" rpy="0 -0 -6.69627e-30" />
      <geometry>
        <mesh filename="package://gripper_description/mesh/dynamixel_horn__list_ndk53xfpevccij_default.stl" />
      </geometry>
      <material name="dynamixel_horn__list_ndk53xfpevccij_default_material">
        <color rgba="0.231373 0.380392 0.705882 1.0" />
      </material>
    </visual>
    <collision>
      <origin xyz="0 0 0.002" rpy="0 -0 -6.69627e-30" />
      <geometry>
        <mesh filename="package://gripper_description/mesh/dynamixel_horn__list_ndk53xfpevccij_default.stl" />
      </geometry>
      <material name="dynamixel_horn__list_ndk53xfpevccij_default_material">
        <color rgba="0.231373 0.380392 0.705882 1.0" />
      </material>
    </collision>
    <inertial>
      <origin xyz="-0.000749317 -0.00574927 -0.0125514" rpy="0 0 0" />
      <mass value="0.008336" />
      <inertia ixx="4.60867e-06" ixy="3.14257e-08" ixz="1.06508e-07" iyy="3.7668e-06" iyz="-4.42417e-07" izz="1.36028e-06" />
    </inertial>
  </link>
  <link name="jaw">
    <visual>
      <origin xyz="0 -0.006 0" rpy="1.47538e-30 1.79172e-32 -1.1553e-30" />
      <geometry>
        <mesh filename="package://gripper_description/mesh/jaw_plate.stl" />
      </geometry>
      <material name="jaw_plate_material">
        <color rgba="0.980392 0.796078 0.262745 1.0" />
      </material>
    </visual>
    <collision>
      <origin xyz="0 -0.006 0" rpy="1.47538e-30 1.79172e-32 -1.1553e-30" />
      <geometry>
        <mesh filename="package://gripper_description/mesh/jaw_plate.stl" />
      </geometry>
      <material name="jaw_plate_material">
        <color rgba="0.980392 0.796078 0.262745 1.0" />
      </material>
    </collision>
    <inertial>
      <origin xyz="0.0084421 0.011184 -7.65795e-10" rpy="0 0 0" />
      <mass value="0.0692262" />
      <inertia ixx="1.03939e-05" ixy="5.20676e-06" ixz="-7.28803e-12" iyy="3.49184e-05" iyz="1.63365e-11" izz="3.29754e-05" />
    </inertial>
  </link>
  <joint name="lhs_j3" type="continuous">
    <origin xyz="0 -0.03 -0.017" rpy="-1.3685e-16 3.07629e-16 3.14159" />
    <parent link="rod_inner_lhs" />
    <child link="jaw" />
    <axis xyz="0 0 1" />
    <limit effort="1" velocity="20" />
    <joint_properties friction="0.0" />
    <mimic joint="lhs_j1" multiplier="-1" offset="0" />
  </joint>
  <joint name="lhs_j1" type="revolute">
    <origin xyz="0.03725 0.015 0.017" rpy="-1.9792e-14 -3.38332e-16 -3.14159" />
    <parent link="body" />
    <child link="rod_inner_lhs" />
    <axis xyz="0 0 1" />
    <limit effort="1" velocity="20" lower="-1.5708" upper="0.15708" />
    <joint_properties friction="0.0" />
  </joint>
  <link name="rod_outer">
    <visual>
      <origin xyz="0.02 0.025 0.0025" rpy="-3.14159 -2.21087e-32 2.27933e-29" />
      <geometry>
        <mesh filename="package://gripper_description/mesh/rod_outer.stl" />
      </geometry>
      <material name="rod_outer_material">
        <color rgba="0.498039 0.498039 0.498039 1.0" />
      </material>
    </visual>
    <collision>
      <origin xyz="0.02 0.025 0.0025" rpy="-3.14159 -2.21087e-32 2.27933e-29" />
      <geometry>
        <mesh filename="package://gripper_description/mesh/rod_outer.stl" />
      </geometry>
      <material name="rod_outer_material">
        <color rgba="0.498039 0.498039 0.498039 1.0" />
      </material>
    </collision>
    <inertial>
      <origin xyz="-3.46945e-18 -0.015 0" rpy="0 0 0" />
      <mass value="0.00147516" />
      <inertia ixx="1.60126e-07" ixy="3.65727e-36" ixz="1.14731e-38" iyy="1.08435e-08" iyz="4.82529e-37" izz="1.64823e-07" />
    </inertial>
  </link>
  <joint name="lhs_j2" type="continuous">
    <origin xyz="0.01725 0.04 -1.25421e-15" rpy="-3.14159 -6.16349e-16 5.9816e-13" />
    <parent link="body" />
    <child link="rod_outer" />
    <axis xyz="0 0 1" />
    <limit effort="1" velocity="20" />
    <joint_properties friction="0.0" />
    <mimic joint="lhs_j1" multiplier="-1" offset="0" />
  </joint>
  <link name="rod_inner_rhs">
    <visual>
      <origin xyz="-0.015 6.93889e-18 -3.46945e-18" rpy="0 -4.93038e-32 1.5708" />
      <geometry>
        <mesh filename="package://gripper_description/mesh/rod_inner_rhs_top.stl" />
      </geometry>
      <material name="rod_inner_rhs_top_material">
        <color rgba="0.768627 0.886275 0.952941 1.0" />
      </material>
    </visual>
    <collision>
      <origin xyz="-0.015 6.93889e-18 -3.46945e-18" rpy="0 -4.93038e-32 1.5708" />
      <geometry>
        <mesh filename="package://gripper_description/mesh/rod_inner_rhs_top.stl" />
      </geometry>
      <material name="rod_inner_rhs_top_material">
        <color rgba="0.768627 0.886275 0.952941 1.0" />
      </material>
    </collision>
    <visual>
      <origin xyz="-0.015 6.93889e-18 -0.007" rpy="1.957e-17 2.77556e-17 1.5708" />
      <geometry>
        <mesh filename="package://gripper_description/mesh/rod_inner_bottom.stl" />
      </geometry>
      <material name="rod_inner_bottom_material">
        <color rgba="0.972549 0.529412 0.00392157 1.0" />
      </material>
    </visual>
    <collision>
      <origin xyz="-0.015 6.93889e-18 -0.007" rpy="1.957e-17 2.77556e-17 1.5708" />
      <geometry>
        <mesh filename="package://gripper_description/mesh/rod_inner_bottom.stl" />
      </geometry>
      <material name="rod_inner_bottom_material">
        <color rgba="0.972549 0.529412 0.00392157 1.0" />
      </material>
    </collision>
    <inertial>
      <origin xyz="0.00698021 0.00083018 0.00134512" rpy="0 0 0" />
      <mass value="0.00680759" />
      <inertia ixx="3.37282e-06" ixy="3.22003e-08" ixz="3.01896e-07" iyy="4.15872e-06" iyz="-1.13906e-07" izz="1.2342e-06" />
    </inertial>
  </link>
  <link name="jaw_2">
    <visual>
      <origin xyz="0 -0.006 3.08149e-33" rpy="0 -0 -1.48493e-31" />
      <geometry>
        <mesh filename="package://gripper_description/mesh/jaw_plate.stl" />
      </geometry>
      <material name="jaw_plate_material">
        <color rgba="0.980392 0.796078 0.262745 1.0" />
      </material>
    </visual>
    <collision>
      <origin xyz="0 -0.006 3.08149e-33" rpy="0 -0 -1.48493e-31" />
      <geometry>
        <mesh filename="package://gripper_description/mesh/jaw_plate.stl" />
      </geometry>
      <material name="jaw_plate_material">
        <color rgba="0.980392 0.796078 0.262745 1.0" />
      </material>
    </collision>
    <inertial>
      <origin xyz="0.0084421 0.011184 -7.65795e-10" rpy="0 0 0" />
      <mass value="0.0692262" />
      <inertia ixx="1.03939e-05" ixy="5.20676e-06" ixz="-7.28803e-12" iyy="3.49184e-05" iyz="1.63365e-11" izz="3.29754e-05" />
    </inertial>
  </link>
  <joint name="rhs_j3" type="continuous">
    <origin xyz="0.03 1.38778e-17 -3.46945e-18" rpy="-3.14159 -8.55478e-24 1.5708" />
    <parent link="rod_inner_rhs" />
    <child link="jaw_2" />
    <axis xyz="0 0 1" />
    <limit effort="1" velocity="20" />
    <joint_properties friction="0.0" />
    <mimic joint="lhs_j1" multiplier="-1" offset="0" />
  </joint>
  <joint name="rhs_j1" type="continuous">
    <origin xyz="0.03725 -0.015 -1.6679e-19" rpy="-3.14417e-16 2.28667e-16 -1.5708" />
    <parent link="body" />
    <child link="rod_inner_rhs" />
    <axis xyz="0 0 1" />
    <limit effort="1" velocity="20" lower="-0.174533" upper="1.5708" />
    <joint_properties friction="0.0" />
    <mimic joint="lhs_j1" multiplier="-1" offset="0" />
  </joint>
  <link name="rod_outer_2">
    <visual>
      <origin xyz="0.02 0.055 0.0025" rpy="3.14159 3.28171e-31 -3.02638e-31" />
      <geometry>
        <mesh filename="package://gripper_description/mesh/rod_outer.stl" />
      </geometry>
      <material name="rod_outer_material">
        <color rgba="0.498039 0.498039 0.498039 1.0" />
      </material>
    </visual>
    <collision>
      <origin xyz="0.02 0.055 0.0025" rpy="3.14159 3.28171e-31 -3.02638e-31" />
      <geometry>
        <mesh filename="package://gripper_description/mesh/rod_outer.stl" />
      </geometry>
      <material name="rod_outer_material">
        <color rgba="0.498039 0.498039 0.498039 1.0" />
      </material>
    </collision>
    <inertial>
      <origin xyz="1.04083e-17 0.015 4.33681e-19" rpy="0 0 0" />
      <mass value="0.00147516" />
      <inertia ixx="1.60126e-07" ixy="-6.53221e-38" ixz="-5.53436e-38" iyy="1.08435e-08" iyz="-7.06994e-39" izz="1.64823e-07" />
    </inertial>
  </link>
  <joint name="rhs_j2" type="continuous">
    <origin xyz="0.01725 -0.04 0" rpy="-3.14159 -4.12648e-15 5.65242e-14" />
    <parent link="body" />
    <child link="rod_outer_2" />
    <axis xyz="0 0 1" />
    <limit effort="1" velocity="20" />
    <joint_properties friction="0.0" />
    <mimic joint="lhs_j1" multiplier="1" offset="0" />
  </joint>
</robot>